Workbook

Sheet How to use
B1: PAMsim simulation planner
B2: Plan your simulations here, then type the values into PAMsim (or Sim.m).
B4: How it works
B5: • Sheet 'Simulations': ONE ROW PER SIMULATION. Left: identification and measurement settings.
B6: • Then 6 species blocks side by side (Species 1, Species 2, ...). Each species has its own name, D, number of
B7: molecules N, brightness and lifetime per colour, and FRET (type and dye distances R). Leave unused species blocks empty.
B8: • Brightness 0 = this species carries no dye of that colour (e.g. a green-red complex: B1 = 0, B2 = 70, B3 = 50).
B9: • Focus per colour: each colour (laser) has its own focus size wr / wz and position dX / dY / dZ (0 = foci overlap).
B10: • FRET: Förster radii R0 are set once per simulation (purple block); per species choose FRET type and distances R.
B11: The FRET efficiency E = 1 / (1 + (R/R0)^6) is calculated for you (grey cells).
B12: • Grey cells are calculated: concentration, FRET efficiency, a check per species, expected count rates, photons, memory.
B13: • Use the + / - buttons above the columns (Excel grouping) to fold species blocks away.
... B37: More than 6 species? Run python make_planner.py --species 10 -o new_planner.xlsx (see the README).

Sheet Column guide
A1: Column | B1: Meaning | C1: Unit | D1: Required? | E1: If left blank
A2: Identification
A3: Sim ID | B3: Unique short name of the simulation (e.g. S12) | C3: - | D3: Required | E3: row is skipped
A4: File name | B4: Name of the simulation: folder <Output folder>/<name>/ with files <name>_1.sim, ... | C4: - | D4: Optional | E4: the Sim ID
A5: Purpose / question | B5: What you want to learn from this simulation | C5: - | D5: Not used | E5: -
A6: Output folder | B6: Main folder; each simulation gets its own subfolder (created automatically) | C6: - | D6: Optional | E6: PAMsim's output folder
A7: Status, Priority | B7: Your bookkeeping | C7: - | D7: Not used | E7: -
A8: Measurement
A9: Box x, y, z | B9: Size of the simulation box; z = 0 gives 2D (membrane) | C9: nm | D9: Optional | E9: 5000 each
A10: Sampling freq. | B10: Time resolution of the random walk (time step = 1/frequency) | C10: kHz | D10: Optional | E10: 1000
A11: Duration | B11: Simulated measurement time per file | C11: s | D11: Required | E11: 10
A12: Frames | B12: Number of frames (relevant for scanning) | C12: - | D12: Optional | E12: 1
A13: Microtime range | B13: TCSPC range (PIE period) | C13: ns | D13: Optional | E13: 80
A14: Scan type | B14: Point / Raster scan / Line scan / Circle scan | C14: - | D14: Optional | E14: Point
A15: Colours | B15: Number of colours = PIE lasers = detection channels (1-3) | C15: - | D15: Required | E15: 1 (brightness 2/3 ignored!)
A16: Background? / Background | B16: Uncorrelated background and its count rate per channel | C16: kHz | D16: Optional | E16: No / 0
A17: IRF? / IRF width | B17: Simulate an instrument response function | C17: ps | D17: Optional | E17: No / 250
A18: Focus per colour and Förster radii
A19: wr 1/2/3 | B19: Lateral 1/e² radius of the focus of each colour (laser) | C19: nm | D19: Optional | E19: 200
A20: wz 1/2/3 | B20: Axial 1/e² radius of the focus of each colour (laser) | C20: nm | D20: Optional | E20: 1000
A21: dX, dY, dZ 1/2/3 | B21: Shift of each colour's focus from the box centre (focus overlap for FCCS) | C21: nm | D21: Optional | E21: 0
A22: R0 1→2, 1→3, 2→3 | B22: Förster radius per dye pair (donor colour → acceptor colour) | C22: Å or nm | D22: Optional | E22: 63, 51, 68
A23: Species blocks (one block per species; leave unused blocks empty)
A24: Name | B24: Name of the species | C24: - | D24: Optional | E24: Species 1, 2, ...
A25: D | B25: Diffusion coefficient | C25: µm²/s | D25: Required | E25: 1
A26: Molecules N | B26: Number of molecules in the box | C26: - | D26: Required | E26: 0 = species absent
A27: Brightness 1/2/3 | B27: Count rate of one molecule in the focus centre per colour; 0 = no dye of this colour | C27: kHz | D27: Required | E27: 0
A28: Lifetime 1/2/3 | B28: Fluorescence lifetime per colour | C28: ns | D28: Optional | E28: 4
A29: FRET | B29: No FRET / Static FRET / Dynamic FRET | C29: - | D29: Optional | E29: No FRET
A30: R 1→2, 1→3, 2→3 | B30: Dye distance for FRET between two colours; only dyes with brightness > 0 take part | C30: Å or nm | D30: Optional | E30: no FRET for this pair
A31: E, Conc., Check (grey) | B31: FRET efficiency 1/(1+(R/R0)^6), concentration, check of the species | C31: -, nM | D31: Calculated | E31: -
A32: Totals, output and results
A33: Exp. rates, Photons, Memory, Check (grey) | B33: Expected count rate per channel (incl. saturation), photons and memory per file, overall check | C33: kHz, M, GB | D33: Calculated | E33: -
A34: Number of files | B34: Independent repeats with the same parameters | C34: - | D34: Optional | E34: 1
A35: Seed | B35: Random seed; file k uses seed + k - 1 | C35: - | D35: Optional | E35: random
A36: Format | B36: .sim (PAM) / .npz / both | C36: - | D36: Optional | E36: .sim
A37: Date run ... Result notes | B37: Your notes after running and analysing | C37: - | D37: Not used | E37: -
A39: Not in the planner (set them in PAMsim after 'Load into editor'): crosstalk, detection efficiency, bleaching, anisotropy, dynamic FRET rates, barrier maps.
A40: Full explanation: planning/PAMsim_planner_guide.docx

Sheet Simulations
A1: Identification | G1: Measurement | T1: Focus per colour | AI1: Förster radii R0 | AL1: Species 1 | BD1: Species 2 | BV1: Species 3 | CN1: Species 4 | DF1: Species 5 | DX1: Species 6 | EP1: Totals and checks (automatic) | EX1: Output | FA1: Results
A3: Sim ID | B3: File name | C3: Purpose / question | D3: Output folder | E3: Status | F3: Priority | G3: Box x [nm] | H3: Box y [nm] | I3: Box z [nm] | J3: Sampling freq. [kHz] | K3: Duration [s] | L3: Frames | M3: Microtime range [ns] | N3: Scan type | O3: Colours | P3: Background? | Q3: Background [kHz/ch] | R3: IRF? | S3: IRF width [ps] | T3: wr 1 [nm] | U3: wr 2 [nm] | V3: wr 3 [nm] | W3: wz 1 [nm] | X3: wz 2 [nm] | Y3: wz 3 [nm] | Z3: dX 1 [nm] | AA3: dX 2 [nm] | AB3: dX 3 [nm] | AC3: dY 1 [nm] | AD3: dY 2 [nm] | AE3: dY 3 [nm] | AF3: dZ 1 [nm] | AG3: dZ 2 [nm] | AH3: dZ 3 [nm] | AI3: R0 1→2 | AJ3: R0 1→3 | AK3: R0 2→3 | AL3: Name | AM3: D [µm²/s] | AN3: Molecules N | AO3: Bright. 1 [kHz] | AP3: Bright. 2 [kHz] | AQ3: Bright. 3 [kHz] | AR3: Lifetime 1 [ns] | AS3: Lifetime 2 [ns] | AT3: Lifetime 3 [ns] | AU3: FRET | AV3: R 1→2 | AW3: R 1→3 | AX3: R 2→3 | AY3: E 1→2 | AZ3: E 1→3 | BA3: E 2→3 | BB3: Conc. [nM] | BC3: Check | BD3: Name | BE3: D [µm²/s] | BF3: Molecules N | BG3: Bright. 1 [kHz] | BH3: Bright. 2 [kHz] | BI3: Bright. 3 [kHz] | BJ3: Lifetime 1 [ns] | BK3: Lifetime 2 [ns] | BL3: Lifetime 3 [ns] | BM3: FRET | BN3: R 1→2 | BO3: R 1→3 | BP3: R 2→3 | BQ3: E 1→2 | BR3: E 1→3 | BS3: E 2→3 | BT3: Conc. [nM] | BU3: Check | BV3: Name | BW3: D [µm²/s] | BX3: Molecules N | BY3: Bright. 1 [kHz] | BZ3: Bright. 2 [kHz] | CA3: Bright. 3 [kHz] | CB3: Lifetime 1 [ns] | CC3: Lifetime 2 [ns] | CD3: Lifetime 3 [ns] | CE3: FRET | CF3: R 1→2 | CG3: R 1→3 | CH3: R 2→3 | CI3: E 1→2 | CJ3: E 1→3 | CK3: E 2→3 | CL3: Conc. [nM] | CM3: Check | CN3: Name | CO3: D [µm²/s] | CP3: Molecules N | CQ3: Bright. 1 [kHz] | CR3: Bright. 2 [kHz] | CS3: Bright. 3 [kHz] | CT3: Lifetime 1 [ns] | CU3: Lifetime 2 [ns] | CV3: Lifetime 3 [ns] | CW3: FRET | CX3: R 1→2 | CY3: R 1→3 | CZ3: R 2→3 | DA3: E 1→2 | DB3: E 1→3 | DC3: E 2→3 | DD3: Conc. [nM] | DE3: Check | DF3: Name | DG3: D [µm²/s] | DH3: Molecules N | DI3: Bright. 1 [kHz] | DJ3: Bright. 2 [kHz] | DK3: Bright. 3 [kHz] | DL3: Lifetime 1 [ns] | DM3: Lifetime 2 [ns] | DN3: Lifetime 3 [ns] | DO3: FRET | DP3: R 1→2 | DQ3: R 1→3 | DR3: R 2→3 | DS3: E 1→2 | DT3: E 1→3 | DU3: E 2→3 | DV3: Conc. [nM] | DW3: Check | DX3: Name | DY3: D [µm²/s] | DZ3: Molecules N | EA3: Bright. 1 [kHz] | EB3: Bright. 2 [kHz] | EC3: Bright. 3 [kHz] | ED3: Lifetime 1 [ns] | EE3: Lifetime 2 [ns] | EF3: Lifetime 3 [ns] | EG3: FRET | EH3: R 1→2 | EI3: R 1→3 | EJ3: R 2→3 | EK3: E 1→2 | EL3: E 1→3 | EM3: E 2→3 | EN3: Conc. [nM] | EO3: Check | EP3: Species used | EQ3: Total molecules | ER3: Exp. rate ch1 [kHz] | ES3: Exp. rate ch2 [kHz] | ET3: Exp. rate ch3 [kHz] | EU3: Photons per file [M] | EV3: Memory per file [GB] | EW3: Check | EX3: Number of files | EY3: Seed | EZ3: Format | FA3: Date run | FB3: Run time [min] | FC3: Fitted D [µm²/s] | FD3: Fitted c [nM] | FE3: Result notes
A4: S00 | B4: example_3C_realistic | C4: EXAMPLE: realistic 3-colour FCCS mixture incl. a static FRET pair (brightness < 10% of freq.) | D4: /Fablab 4/Users/Fabio/PhD/Projects/3C_FCCS/Simulation | E4: Idea | F4: 1 | G4: 5000 | H4: 5000 | I4: 5000 | J4: 1000 | K4: 60 | L4: 1 | M4: 60 | N4: Point | O4: 3 | P4: No | Q4: 0.2 | R4: No | S4: 250 | T4: 180 | U4: 210 | V4: 240 | W4: 900 | X4: 1050 | Y4: 1200 | Z4: 0 | AA4: 0 | AB4: 0 | AC4: 0 | AD4: 0 | AE4: 0 | AF4: 0 | AG4: 0 | AH4: 100 | AI4: 63 | AJ4: 51 | AK4: 68 | AL4: triple complex | AM4: 35 | AN4: 300 | AO4: 100 | AP4: 70 | AQ4: 50 | AR4: 4 | AS4: 3 | AT4: 2 | AU4: No FRET | AY4: =IF(OR($AU4="",$AU4="No FRET",N($AV4)<=0,N(IF($AI4="",63,$AI4))<=0),"",1/(1+($AV4/IF($AI4="",63,$AI4))^6)) | AZ4: =IF(OR($AU4="",$AU4="No FRET",N($AW4)<=0,N(IF($AJ4="",51,$AJ4))<=0),"",1/(1+($AW4/IF($AJ4="",51,$AJ4))^6)) | BA4: =IF(OR($AU4="",$AU4="No FRET",N($AX4)<=0,N(IF($AK4="",68,$AK4))<=0),"",1/(1+($AX4/IF($AK4="",68,$AK4))^6)) | BB4: =IF(OR($A4="",N($AN4)<=0),"",IF(IF($I4="",5000,$I4)>0,$AN4/(IF($G4="",5000,$G4)*IF($H4="",5000,$H4)*IF($I4="",5000,$I4))/1E-024/6.022E+023/0.000000001,"")) -> 3.9853869 | BC4: =IF(Calc!G4=0,"",IF(Calc!E4>=1,"✖ saturated (B ≥ freq.)",IF(Calc!E4>0.1,"⚠ B > 10% of freq.",IF(Calc!E4=0,"⚠ no brightness",IF(Calc!F4>0.1,"⚠ step > 10% of wr",IF(OR(AND(N($AQ4)>0,IF($O4="",1,$O4)<3),AND(N($AP4)>0,IF($O4="",1,$O4)<2)),"⚠ uses a colour above Colours = "&IF($O4="",1,$O4)&" (ignored)",IF(AND($AU4<>"",$AU4<>"No FRET",N(IF($O4="",1,$O4))<2),"⚠ FRET needs ≥ 2 colours",IF(AND($AU4<>"",$AU4<>"No FRET",N($AV4)+N($AW4)+N($AX4)=0),"⚠ FRET: set R","✔ OK")))))))) -> ✔ OK | BD4: blue-green | BE4: 35 | BF4: 200 | BG4: 100 | BH4: 70 | BI4: 0 | BJ4: 4 | BK4: 3 | BL4: 2 | BM4: No FRET | BQ4: =IF(OR($BM4="",$BM4="No FRET",N($BN4)<=0,N(IF($AI4="",63,$AI4))<=0),"",1/(1+($BN4/IF($AI4="",63,$AI4))^6)) | BR4: =IF(OR($BM4="",$BM4="No FRET",N($BO4)<=0,N(IF($AJ4="",51,$AJ4))<=0),"",1/(1+($BO4/IF($AJ4="",51,$AJ4))^6)) | BS4: =IF(OR($BM4="",$BM4="No FRET",N($BP4)<=0,N(IF($AK4="",68,$AK4))<=0),"",1/(1+($BP4/IF($AK4="",68,$AK4))^6)) | BT4: =IF(OR($A4="",N($BF4)<=0),"",IF(IF($I4="",5000,$I4)>0,$BF4/(IF($G4="",5000,$G4)*IF($H4="",5000,$H4)*IF($I4="",5000,$I4))/1E-024/6.022E+023/0.000000001,"")) -> 2.6569246 | BU4: =IF(Calc!M4=0,"",IF(Calc!K4>=1,"✖ saturated (B ≥ freq.)",IF(Calc!K4>0.1,"⚠ B > 10% of freq.",IF(Calc!K4=0,"⚠ no brightness",IF(Calc!L4>0.1,"⚠ step > 10% of wr",IF(OR(AND(N($BI4)>0,IF($O4="",1,$O4)<3),AND(N($BH4)>0,IF($O4="",1,$O4)<2)),"⚠ uses a colour above Colours = "&IF($O4="",1,$O4)&" (ignored)",IF(AND($BM4<>"",$BM4<>"No FRET",N(IF($O4="",1,$O4))<2),"⚠ FRET needs ≥ 2 colours",IF(AND($BM4<>"",$BM4<>"No FRET",N($BN4)+N($BO4)+N($BP4)=0),"⚠ FRET: set R","✔ OK")))))))) -> ✔ OK | BV4: green-red | BW4: 35 | BX4: 200 | BY4: 0 | BZ4: 70 | CA4: 50 | CB4: 4 | CC4: 3 | CD4: 2 | CE4: No FRET | CI4: =IF(OR($CE4="",$CE4="No FRET",N($CF4)<=0,N(IF($AI4="",63,$AI4))<=0),"",1/(1+($CF4/IF($AI4="",63,$AI4))^6)) | CJ4: =IF(OR($CE4="",$CE4="No FRET",N($CG4)<=0,N(IF($AJ4="",51,$AJ4))<=0),"",1/(1+($CG4/IF($AJ4="",51,$AJ4))^6)) | CK4: =IF(OR($CE4="",$CE4="No FRET",N($CH4)<=0,N(IF($AK4="",68,$AK4))<=0),"",1/(1+($CH4/IF($AK4="",68,$AK4))^6)) | CL4: =IF(OR($A4="",N($BX4)<=0),"",IF(IF($I4="",5000,$I4)>0,$BX4/(IF($G4="",5000,$G4)*IF($H4="",5000,$H4)*IF($I4="",5000,$I4))/1E-024/6.022E+023/0.000000001,"")) -> 2.6569246 | CM4: =IF(Calc!S4=0,"",IF(Calc!Q4>=1,"✖ saturated (B ≥ freq.)",IF(Calc!Q4>0.1,"⚠ B > 10% of freq.",IF(Calc!Q4=0,"⚠ no brightness",IF(Calc!R4>0.1,"⚠ step > 10% of wr",IF(OR(AND(N($CA4)>0,IF($O4="",1,$O4)<3),AND(N($BZ4)>0,IF($O4="",1,$O4)<2)),"⚠ uses a colour above Colours = "&IF($O4="",1,$O4)&" (ignored)",IF(AND($CE4<>"",$CE4<>"No FRET",N(IF($O4="",1,$O4))<2),"⚠ FRET needs ≥ 2 colours",IF(AND($CE4<>"",$CE4<>"No FRET",N($CF4)+N($CG4)+N($CH4)=0),"⚠ FRET: set R","✔ OK")))))))) -> ✔ OK | CN4: FRET pair 1-2 | CO4: 50 | CP4: 100 | CQ4: 100 | CR4: 70 | CS4: 0 | CT4: 4 | CU4: 3 | CV4: 2 | CW4: Static FRET | CX4: 50 | DA4: =IF(OR($CW4="",$CW4="No FRET",N($CX4)<=0,N(IF($AI4="",63,$AI4))<=0),"",1/(1+($CX4/IF($AI4="",63,$AI4))^6)) -> 0.80006015 | DB4: =IF(OR($CW4="",$CW4="No FRET",N($CY4)<=0,N(IF($AJ4="",51,$AJ4))<=0),"",1/(1+($CY4/IF($AJ4="",51,$AJ4))^6)) | DC4: =IF(OR($CW4="",$CW4="No FRET",N($CZ4)<=0,N(IF($AK4="",68,$AK4))<=0),"",1/(1+($CZ4/IF($AK4="",68,$AK4))^6)) | DD4: =IF(OR($A4="",N($CP4)<=0),"",IF(IF($I4="",5000,$I4)>0,$CP4/(IF($G4="",5000,$G4)*IF($H4="",5000,$H4)*IF($I4="",5000,$I4))/1E-024/6.022E+023/0.000000001,"")) -> 1.3284623 | DE4: =IF(Calc!Y4=0,"",IF(Calc!W4>=1,"✖ saturated (B ≥ freq.)",IF(Calc!W4>0.1,"⚠ B > 10% of freq.",IF(Calc!W4=0,"⚠ no brightness",IF(Calc!X4>0.1,"⚠ step > 10% of wr",IF(OR(AND(N($CS4)>0,IF($O4="",1,$O4)<3),AND(N($CR4)>0,IF($O4="",1,$O4)<2)),"⚠ uses a colour above Colours = "&IF($O4="",1,$O4)&" (ignored)",IF(AND($CW4<>"",$CW4<>"No FRET",N(IF($O4="",1,$O4))<2),"⚠ FRET needs ≥ 2 colours",IF(AND($CW4<>"",$CW4<>"No FRET",N($CX4)+N($CY4)+N($CZ4)=0),"⚠ FRET: set R","✔ OK")))))))) -> ✔ OK | DS4: =IF(OR($DO4="",$DO4="No FRET",N($DP4)<=0,N(IF($AI4="",63,$AI4))<=0),"",1/(1+($DP4/IF($AI4="",63,$AI4))^6)) | DT4: =IF(OR($DO4="",$DO4="No FRET",N($DQ4)<=0,N(IF($AJ4="",51,$AJ4))<=0),"",1/(1+($DQ4/IF($AJ4="",51,$AJ4))^6)) | DU4: =IF(OR($DO4="",$DO4="No FRET",N($DR4)<=0,N(IF($AK4="",68,$AK4))<=0),"",1/(1+($DR4/IF($AK4="",68,$AK4))^6)) | DV4: =IF(OR($A4="",N($DH4)<=0),"",IF(IF($I4="",5000,$I4)>0,$DH4/(IF($G4="",5000,$G4)*IF($H4="",5000,$H4)*IF($I4="",5000,$I4))/1E-024/6.022E+023/0.000000001,"")) | DW4: =IF(Calc!AE4=0,"",IF(Calc!AC4>=1,"✖ saturated (B ≥ freq.)",IF(Calc!AC4>0.1,"⚠ B > 10% of freq.",IF(Calc!AC4=0,"⚠ no brightness",IF(Calc!AD4>0.1,"⚠ step > 10% of wr",IF(OR(AND(N($DK4)>0,IF($O4="",1,$O4)<3),AND(N($DJ4)>0,IF($O4="",1,$O4)<2)),"⚠ uses a colour above Colours = "&IF($O4="",1,$O4)&" (ignored)",IF(AND($DO4<>"",$DO4<>"No FRET",N(IF($O4="",1,$O4))<2),"⚠ FRET needs ≥ 2 colours",IF(AND($DO4<>"",$DO4<>"No FRET",N($DP4)+N($DQ4)+N($DR4)=0),"⚠ FRET: set R","✔ OK")))))))) | EK4: =IF(OR($EG4="",$EG4="No FRET",N($EH4)<=0,N(IF($AI4="",63,$AI4))<=0),"",1/(1+($EH4/IF($AI4="",63,$AI4))^6)) | EL4: =IF(OR($EG4="",$EG4="No FRET",N($EI4)<=0,N(IF($AJ4="",51,$AJ4))<=0),"",1/(1+($EI4/IF($AJ4="",51,$AJ4))^6)) | EM4: =IF(OR($EG4="",$EG4="No FRET",N($EJ4)<=0,N(IF($AK4="",68,$AK4))<=0),"",1/(1+($EJ4/IF($AK4="",68,$AK4))^6)) | EN4: =IF(OR($A4="",N($DZ4)<=0),"",IF(IF($I4="",5000,$I4)>0,$DZ4/(IF($G4="",5000,$G4)*IF($H4="",5000,$H4)*IF($I4="",5000,$I4))/1E-024/6.022E+023/0.000000001,"")) | EO4: =IF(Calc!AK4=0,"",IF(Calc!AI4>=1,"✖ saturated (B ≥ freq.)",IF(Calc!AI4>0.1,"⚠ B > 10% of freq.",IF(Calc!AI4=0,"⚠ no brightness",IF(Calc!AJ4>0.1,"⚠ step > 10% of wr",IF(OR(AND(N($EC4)>0,IF($O4="",1,$O4)<3),AND(N($EB4)>0,IF($O4="",1,$O4)<2)),"⚠ uses a colour above Colours = "&IF($O4="",1,$O4)&" (ignored)",IF(AND($EG4<>"",$EG4<>"No FRET",N(IF($O4="",1,$O4))<2),"⚠ FRET needs ≥ 2 colours",IF(AND($EG4<>"",$EG4<>"No FRET",N($EH4)+N($EI4)+N($EJ4)=0),"⚠ FRET: set R","✔ OK")))))))) | EP4: =IF($A4="","",SUM(Calc!G4,Calc!M4,Calc!S4,Calc!Y4,Calc!AE4,Calc!AK4)) -> 4 | EQ4: =IF($A4="","",N($AN4)+N($BF4)+N($BX4)+N($CP4)+N($DH4)+N($DZ4)) -> 800 | ER4: =IF($A4="","",SUM(Calc!B4,Calc!H4,Calc!N4,Calc!T4,Calc!Z4,Calc!AF4)) -> 27.555518 | ES4: =IF($A4="","",SUM(Calc!C4,Calc!I4,Calc!O4,Calc!U4,Calc!AA4,Calc!AG4)) -> 40.839999 | ET4: =IF($A4="","",SUM(Calc!D4,Calc!J4,Calc!P4,Calc!V4,Calc!AB4,Calc!AH4)) -> 27.215326 | EU4: =IF($A4="","",($ER4+$ES4+$ET4+IF($P4="Yes",N($Q4)*N(IF($O4="",1,$O4)),0))*1000*IF($K4="",10,$K4)/1000000) -> 5.7366505 | EV4: =IF($A4="","",$EU4*1000000*12/1000000000) -> 0.068839806 | EW4: =IF($A4="","",IF($EP4=0,"⚠ no species entered",IF(((LEFT($BC4,1)="✖")+(LEFT($BU4,1)="✖")+(LEFT($CM4,1)="✖")+(LEFT($DE4,1)="✖")+(LEFT($DW4,1)="✖")+(LEFT($EO4,1)="✖"))>0,"✖ "&((LEFT($BC4,1)="✖")+(LEFT($BU4,1)="✖")+(LEFT($CM4,1)="✖")+(LEFT($DE4,1)="✖")+(LEFT($DW4,1)="✖")+(LEFT($EO4,1)="✖"))&" species saturated - see the species checks",IF(MIN(IF($G4="",5000,$G4),IF($H4="",5000,$H4))<8*MAX(IF($T4="",200,$T4),IF($U4="",200,$U4),IF($V4="",200,$V4)),"⚠ box too small laterally (< 8·wr)",IF(AND(IF($I4="",5000,$I4)>0,IF($I4="",5000,$I4)<3*MAX(IF($W4="",1000,$W4),IF($X4="",1000,$X4),IF($Y4="",1000,$Y4))),"⚠ box too small axially (< 3·wz)",IF($EV4>8,"⚠ > 8 GB per file: shorten the duration and use several files",IF(((LEFT($BC4,1)="⚠")+(LEFT($BU4,1)="⚠")+(LEFT($CM4,1)="⚠")+(LEFT($DE4,1)="⚠")+(LEFT($DW4,1)="⚠")+(LEFT($EO4,1)="⚠"))>0,"⚠ "&((LEFT($BC4,1)="⚠")+(LEFT($BU4,1)="⚠")+(LEFT($CM4,1)="⚠")+(LEFT($DE4,1)="⚠")+(LEFT($DW4,1)="⚠")+(LEFT($EO4,1)="⚠"))&" species with a warning","✔ OK"))))))) -> ✔ OK | EX4: 1 | EZ4: .sim | FE4: Example row - shows the expected format
A5: S01 | B5: Simulation_800N_15D_200wr_1000wz_60s_60ns | C5: Just to see if the code works | D5: /Fablab 4/Users/Fabio/PhD/Projects/3C_FCCS/Simulation | E5: Planned | F5: 2 | G5: 5000 | H5: 5000 | I5: 5000 | J5: 1000 | K5: 60 | L5: 1 | M5: 60 | N5: Point | O5: 3 | P5: No | Q5: 0.2 | R5: No | S5: 250 | T5: 200 | U5: 200 | V5: 200 | W5: 1000 | X5: 1000 | Y5: 1000 | Z5: 0 | AA5: 0 | AB5: 0 | AC5: 0 | AD5: 0 | AE5: 0 | AF5: 0 | AG5: 0 | AH5: 0 | AI5: 63 | AJ5: 51 | AK5: 68 | AL5: Species 1 | AM5: 15 | AN5: 800 | AO5: 50 | AP5: 50 | AQ5: 50 | AR5: 4 | AS5: 3 | AT5: 2 | AU5: No FRET | AY5: =IF(OR($AU5="",$AU5="No FRET",N($AV5)<=0,N(IF($AI5="",63,$AI5))<=0),"",1/(1+($AV5/IF($AI5="",63,$AI5))^6)) | AZ5: =IF(OR($AU5="",$AU5="No FRET",N($AW5)<=0,N(IF($AJ5="",51,$AJ5))<=0),"",1/(1+($AW5/IF($AJ5="",51,$AJ5))^6)) | BA5: =IF(OR($AU5="",$AU5="No FRET",N($AX5)<=0,N(IF($AK5="",68,$AK5))<=0),"",1/(1+($AX5/IF($AK5="",68,$AK5))^6)) | BB5: =IF(OR($A5="",N($AN5)<=0),"",IF(IF($I5="",5000,$I5)>0,$AN5/(IF($G5="",5000,$G5)*IF($H5="",5000,$H5)*IF($I5="",5000,$I5))/1E-024/6.022E+023/0.000000001,"")) -> 10.627698 | BC5: =IF(Calc!G5=0,"",IF(Calc!E5>=1,"✖ saturated (B ≥ freq.)",IF(Calc!E5>0.1,"⚠ B > 10% of freq.",IF(Calc!E5=0,"⚠ no brightness",IF(Calc!F5>0.1,"⚠ step > 10% of wr",IF(OR(AND(N($AQ5)>0,IF($O5="",1,$O5)<3),AND(N($AP5)>0,IF($O5="",1,$O5)<2)),"⚠ uses a colour above Colours = "&IF($O5="",1,$O5)&" (ignored)",IF(AND($AU5<>"",$AU5<>"No FRET",N(IF($O5="",1,$O5))<2),"⚠ FRET needs ≥ 2 colours",IF(AND($AU5<>"",$AU5<>"No FRET",N($AV5)+N($AW5)+N($AX5)=0),"⚠ FRET: set R","✔ OK")))))))) -> ✔ OK | BQ5: =IF(OR($BM5="",$BM5="No FRET",N($BN5)<=0,N(IF($AI5="",63,$AI5))<=0),"",1/(1+($BN5/IF($AI5="",63,$AI5))^6)) | BR5: =IF(OR($BM5="",$BM5="No FRET",N($BO5)<=0,N(IF($AJ5="",51,$AJ5))<=0),"",1/(1+($BO5/IF($AJ5="",51,$AJ5))^6)) | BS5: =IF(OR($BM5="",$BM5="No FRET",N($BP5)<=0,N(IF($AK5="",68,$AK5))<=0),"",1/(1+($BP5/IF($AK5="",68,$AK5))^6)) | BT5: =IF(OR($A5="",N($BF5)<=0),"",IF(IF($I5="",5000,$I5)>0,$BF5/(IF($G5="",5000,$G5)*IF($H5="",5000,$H5)*IF($I5="",5000,$I5))/1E-024/6.022E+023/0.000000001,"")) | BU5: =IF(Calc!M5=0,"",IF(Calc!K5>=1,"✖ saturated (B ≥ freq.)",IF(Calc!K5>0.1,"⚠ B > 10% of freq.",IF(Calc!K5=0,"⚠ no brightness",IF(Calc!L5>0.1,"⚠ step > 10% of wr",IF(OR(AND(N($BI5)>0,IF($O5="",1,$O5)<3),AND(N($BH5)>0,IF($O5="",1,$O5)<2)),"⚠ uses a colour above Colours = "&IF($O5="",1,$O5)&" (ignored)",IF(AND($BM5<>"",$BM5<>"No FRET",N(IF($O5="",1,$O5))<2),"⚠ FRET needs ≥ 2 colours",IF(AND($BM5<>"",$BM5<>"No FRET",N($BN5)+N($BO5)+N($BP5)=0),"⚠ FRET: set R","✔ OK")))))))) | CI5: =IF(OR($CE5="",$CE5="No FRET",N($CF5)<=0,N(IF($AI5="",63,$AI5))<=0),"",1/(1+($CF5/IF($AI5="",63,$AI5))^6)) | CJ5: =IF(OR($CE5="",$CE5="No FRET",N($CG5)<=0,N(IF($AJ5="",51,$AJ5))<=0),"",1/(1+($CG5/IF($AJ5="",51,$AJ5))^6)) | CK5: =IF(OR($CE5="",$CE5="No FRET",N($CH5)<=0,N(IF($AK5="",68,$AK5))<=0),"",1/(1+($CH5/IF($AK5="",68,$AK5))^6)) | CL5: =IF(OR($A5="",N($BX5)<=0),"",IF(IF($I5="",5000,$I5)>0,$BX5/(IF($G5="",5000,$G5)*IF($H5="",5000,$H5)*IF($I5="",5000,$I5))/1E-024/6.022E+023/0.000000001,"")) | CM5: =IF(Calc!S5=0,"",IF(Calc!Q5>=1,"✖ saturated (B ≥ freq.)",IF(Calc!Q5>0.1,"⚠ B > 10% of freq.",IF(Calc!Q5=0,"⚠ no brightness",IF(Calc!R5>0.1,"⚠ step > 10% of wr",IF(OR(AND(N($CA5)>0,IF($O5="",1,$O5)<3),AND(N($BZ5)>0,IF($O5="",1,$O5)<2)),"⚠ uses a colour above Colours = "&IF($O5="",1,$O5)&" (ignored)",IF(AND($CE5<>"",$CE5<>"No FRET",N(IF($O5="",1,$O5))<2),"⚠ FRET needs ≥ 2 colours",IF(AND($CE5<>"",$CE5<>"No FRET",N($CF5)+N($CG5)+N($CH5)=0),"⚠ FRET: set R","✔ OK")))))))) | DA5: =IF(OR($CW5="",$CW5="No FRET",N($CX5)<=0,N(IF($AI5="",63,$AI5))<=0),"",1/(1+($CX5/IF($AI5="",63,$AI5))^6)) | DB5: =IF(OR($CW5="",$CW5="No FRET",N($CY5)<=0,N(IF($AJ5="",51,$AJ5))<=0),"",1/(1+($CY5/IF($AJ5="",51,$AJ5))^6)) | DC5: =IF(OR($CW5="",$CW5="No FRET",N($CZ5)<=0,N(IF($AK5="",68,$AK5))<=0),"",1/(1+($CZ5/IF($AK5="",68,$AK5))^6)) | DD5: =IF(OR($A5="",N($CP5)<=0),"",IF(IF($I5="",5000,$I5)>0,$CP5/(IF($G5="",5000,$G5)*IF($H5="",5000,$H5)*IF($I5="",5000,$I5))/1E-024/6.022E+023/0.000000001,"")) | DE5: =IF(Calc!Y5=0,"",IF(Calc!W5>=1,"✖ saturated (B ≥ freq.)",IF(Calc!W5>0.1,"⚠ B > 10% of freq.",IF(Calc!W5=0,"⚠ no brightness",IF(Calc!X5>0.1,"⚠ step > 10% of wr",IF(OR(AND(N($CS5)>0,IF($O5="",1,$O5)<3),AND(N($CR5)>0,IF($O5="",1,$O5)<2)),"⚠ uses a colour above Colours = "&IF($O5="",1,$O5)&" (ignored)",IF(AND($CW5<>"",$CW5<>"No FRET",N(IF($O5="",1,$O5))<2),"⚠ FRET needs ≥ 2 colours",IF(AND($CW5<>"",$CW5<>"No FRET",N($CX5)+N($CY5)+N($CZ5)=0),"⚠ FRET: set R","✔ OK")))))))) | DS5: =IF(OR($DO5="",$DO5="No FRET",N($DP5)<=0,N(IF($AI5="",63,$AI5))<=0),"",1/(1+($DP5/IF($AI5="",63,$AI5))^6)) | DT5: =IF(OR($DO5="",$DO5="No FRET",N($DQ5)<=0,N(IF($AJ5="",51,$AJ5))<=0),"",1/(1+($DQ5/IF($AJ5="",51,$AJ5))^6)) | DU5: =IF(OR($DO5="",$DO5="No FRET",N($DR5)<=0,N(IF($AK5="",68,$AK5))<=0),"",1/(1+($DR5/IF($AK5="",68,$AK5))^6)) | DV5: =IF(OR($A5="",N($DH5)<=0),"",IF(IF($I5="",5000,$I5)>0,$DH5/(IF($G5="",5000,$G5)*IF($H5="",5000,$H5)*IF($I5="",5000,$I5))/1E-024/6.022E+023/0.000000001,"")) | DW5: =IF(Calc!AE5=0,"",IF(Calc!AC5>=1,"✖ saturated (B ≥ freq.)",IF(Calc!AC5>0.1,"⚠ B > 10% of freq.",IF(Calc!AC5=0,"⚠ no brightness",IF(Calc!AD5>0.1,"⚠ step > 10% of wr",IF(OR(AND(N($DK5)>0,IF($O5="",1,$O5)<3),AND(N($DJ5)>0,IF($O5="",1,$O5)<2)),"⚠ uses a colour above Colours = "&IF($O5="",1,$O5)&" (ignored)",IF(AND($DO5<>"",$DO5<>"No FRET",N(IF($O5="",1,$O5))<2),"⚠ FRET needs ≥ 2 colours",IF(AND($DO5<>"",$DO5<>"No FRET",N($DP5)+N($DQ5)+N($DR5)=0),"⚠ FRET: set R","✔ OK")))))))) | EK5: =IF(OR($EG5="",$EG5="No FRET",N($EH5)<=0,N(IF($AI5="",63,$AI5))<=0),"",1/(1+($EH5/IF($AI5="",63,$AI5))^6)) | EL5: =IF(OR($EG5="",$EG5="No FRET",N($EI5)<=0,N(IF($AJ5="",51,$AJ5))<=0),"",1/(1+($EI5/IF($AJ5="",51,$AJ5))^6)) | EM5: =IF(OR($EG5="",$EG5="No FRET",N($EJ5)<=0,N(IF($AK5="",68,$AK5))<=0),"",1/(1+($EJ5/IF($AK5="",68,$AK5))^6)) | EN5: =IF(OR($A5="",N($DZ5)<=0),"",IF(IF($I5="",5000,$I5)>0,$DZ5/(IF($G5="",5000,$G5)*IF($H5="",5000,$H5)*IF($I5="",5000,$I5))/1E-024/6.022E+023/0.000000001,"")) | EO5: =IF(Calc!AK5=0,"",IF(Calc!AI5>=1,"✖ saturated (B ≥ freq.)",IF(Calc!AI5>0.1,"⚠ B > 10% of freq.",IF(Calc!AI5=0,"⚠ no brightness",IF(Calc!AJ5>0.1,"⚠ step > 10% of wr",IF(OR(AND(N($EC5)>0,IF($O5="",1,$O5)<3),AND(N($EB5)>0,IF($O5="",1,$O5)<2)),"⚠ uses a colour above Colours = "&IF($O5="",1,$O5)&" (ignored)",IF(AND($EG5<>"",$EG5<>"No FRET",N(IF($O5="",1,$O5))<2),"⚠ FRET needs ≥ 2 colours",IF(AND($EG5<>"",$EG5<>"No FRET",N($EH5)+N($EI5)+N($EJ5)=0),"⚠ FRET: set R","✔ OK")))))))) | EP5: =IF($A5="","",SUM(Calc!G5,Calc!M5,Calc!S5,Calc!Y5,Calc!AE5,Calc!AK5)) -> 1 | EQ5: =IF($A5="","",N($AN5)+N($BF5)+N($BX5)+N($CP5)+N($DH5)+N($DZ5)) -> 800 | ER5: =IF($A5="","",SUM(Calc!B5,Calc!H5,Calc!N5,Calc!T5,Calc!Z5,Calc!AF5)) -> 25.199376 | ES5: =IF($A5="","",SUM(Calc!C5,Calc!I5,Calc!O5,Calc!U5,Calc!AA5,Calc!AG5)) -> 25.199376 | ET5: =IF($A5="","",SUM(Calc!D5,Calc!J5,Calc!P5,Calc!V5,Calc!AB5,Calc!AH5)) -> 25.199376 | EU5: =IF($A5="","",($ER5+$ES5+$ET5+IF($P5="Yes",N($Q5)*N(IF($O5="",1,$O5)),0))*1000*IF($K5="",10,$K5)/1000000) -> 4.5358877 | EV5: =IF($A5="","",$EU5*1000000*12/1000000000) -> 0.054430652 | EW5: =IF($A5="","",IF($EP5=0,"⚠ no species entered",IF(((LEFT($BC5,1)="✖")+(LEFT($BU5,1)="✖")+(LEFT($CM5,1)="✖")+(LEFT($DE5,1)="✖")+(LEFT($DW5,1)="✖")+(LEFT($EO5,1)="✖"))>0,"✖ "&((LEFT($BC5,1)="✖")+(LEFT($BU5,1)="✖")+(LEFT($CM5,1)="✖")+(LEFT($DE5,1)="✖")+(LEFT($DW5,1)="✖")+(LEFT($EO5,1)="✖"))&" species saturated - see the species checks",IF(MIN(IF($G5="",5000,$G5),IF($H5="",5000,$H5))<8*MAX(IF($T5="",200,$T5),IF($U5="",200,$U5),IF($V5="",200,$V5)),"⚠ box too small laterally (< 8·wr)",IF(AND(IF($I5="",5000,$I5)>0,IF($I5="",5000,$I5)<3*MAX(IF($W5="",1000,$W5),IF($X5="",1000,$X5),IF($Y5="",1000,$Y5))),"⚠ box too small axially (< 3·wz)",IF($EV5>8,"⚠ > 8 GB per file: shorten the duration and use several files",IF(((LEFT($BC5,1)="⚠")+(LEFT($BU5,1)="⚠")+(LEFT($CM5,1)="⚠")+(LEFT($DE5,1)="⚠")+(LEFT($DW5,1)="⚠")+(LEFT($EO5,1)="⚠"))>0,"⚠ "&((LEFT($BC5,1)="⚠")+(LEFT($BU5,1)="⚠")+(LEFT($CM5,1)="⚠")+(LEFT($DE5,1)="⚠")+(LEFT($DW5,1)="⚠")+(LEFT($EO5,1)="⚠"))&" species with a warning","✔ OK"))))))) -> ✔ OK | EX5: 1 | EZ5: .sim | FE5: from Simulation_parameters.xlsx (box size assumed)
A6: S02 | B6: Simulation_100Nx3_200wr_1000wz_60s_60ns_3colorXspecies | C6: To verify that no 3C cross-correlation would arise | D6: /Fablab 4/Users/Fabio/PhD/Projects/3C_FCCS/Simulation | E6: Planned | F6: 2 | G6: 5000 | H6: 5000 | I6: 5000 | J6: 1000 | K6: 60 | L6: 1 | M6: 60 | N6: Point | O6: 3 | P6: No | Q6: 0.2 | R6: No | S6: 250 | T6: 200 | U6: 200 | V6: 200 | W6: 1000 | X6: 1000 | Y6: 1000 | Z6: 0 | AA6: 0 | AB6: 0 | AC6: 0 | AD6: 0 | AE6: 0 | AF6: 0 | AG6: 0 | AH6: 0 | AI6: 63 | AJ6: 51 | AK6: 68 | AL6: Species 1 | AM6: 50 | AN6: 800 | AO6: 50 | AP6: 50 | AQ6: 0 | AR6: 4 | AS6: 3 | AT6: 2 | AU6: No FRET | AY6: =IF(OR($AU6="",$AU6="No FRET",N($AV6)<=0,N(IF($AI6="",63,$AI6))<=0),"",1/(1+($AV6/IF($AI6="",63,$AI6))^6)) | AZ6: =IF(OR($AU6="",$AU6="No FRET",N($AW6)<=0,N(IF($AJ6="",51,$AJ6))<=0),"",1/(1+($AW6/IF($AJ6="",51,$AJ6))^6)) | BA6: =IF(OR($AU6="",$AU6="No FRET",N($AX6)<=0,N(IF($AK6="",68,$AK6))<=0),"",1/(1+($AX6/IF($AK6="",68,$AK6))^6)) | BB6: =IF(OR($A6="",N($AN6)<=0),"",IF(IF($I6="",5000,$I6)>0,$AN6/(IF($G6="",5000,$G6)*IF($H6="",5000,$H6)*IF($I6="",5000,$I6))/1E-024/6.022E+023/0.000000001,"")) -> 10.627698 | BC6: =IF(Calc!G6=0,"",IF(Calc!E6>=1,"✖ saturated (B ≥ freq.)",IF(Calc!E6>0.1,"⚠ B > 10% of freq.",IF(Calc!E6=0,"⚠ no brightness",IF(Calc!F6>0.1,"⚠ step > 10% of wr",IF(OR(AND(N($AQ6)>0,IF($O6="",1,$O6)<3),AND(N($AP6)>0,IF($O6="",1,$O6)<2)),"⚠ uses a colour above Colours = "&IF($O6="",1,$O6)&" (ignored)",IF(AND($AU6<>"",$AU6<>"No FRET",N(IF($O6="",1,$O6))<2),"⚠ FRET needs ≥ 2 colours",IF(AND($AU6<>"",$AU6<>"No FRET",N($AV6)+N($AW6)+N($AX6)=0),"⚠ FRET: set R","✔ OK")))))))) -> ✔ OK | BD6: Species 2 | BE6: 50 | BF6: 100 | BG6: 50 | BH6: 0 | BI6: 50 | BJ6: 4 | BK6: 3 | BL6: 2 | BM6: No FRET | BQ6: =IF(OR($BM6="",$BM6="No FRET",N($BN6)<=0,N(IF($AI6="",63,$AI6))<=0),"",1/(1+($BN6/IF($AI6="",63,$AI6))^6)) | BR6: =IF(OR($BM6="",$BM6="No FRET",N($BO6)<=0,N(IF($AJ6="",51,$AJ6))<=0),"",1/(1+($BO6/IF($AJ6="",51,$AJ6))^6)) | BS6: =IF(OR($BM6="",$BM6="No FRET",N($BP6)<=0,N(IF($AK6="",68,$AK6))<=0),"",1/(1+($BP6/IF($AK6="",68,$AK6))^6)) | BT6: =IF(OR($A6="",N($BF6)<=0),"",IF(IF($I6="",5000,$I6)>0,$BF6/(IF($G6="",5000,$G6)*IF($H6="",5000,$H6)*IF($I6="",5000,$I6))/1E-024/6.022E+023/0.000000001,"")) -> 1.3284623 | BU6: =IF(Calc!M6=0,"",IF(Calc!K6>=1,"✖ saturated (B ≥ freq.)",IF(Calc!K6>0.1,"⚠ B > 10% of freq.",IF(Calc!K6=0,"⚠ no brightness",IF(Calc!L6>0.1,"⚠ step > 10% of wr",IF(OR(AND(N($BI6)>0,IF($O6="",1,$O6)<3),AND(N($BH6)>0,IF($O6="",1,$O6)<2)),"⚠ uses a colour above Colours = "&IF($O6="",1,$O6)&" (ignored)",IF(AND($BM6<>"",$BM6<>"No FRET",N(IF($O6="",1,$O6))<2),"⚠ FRET needs ≥ 2 colours",IF(AND($BM6<>"",$BM6<>"No FRET",N($BN6)+N($BO6)+N($BP6)=0),"⚠ FRET: set R","✔ OK")))))))) -> ✔ OK | BV6: Species 3 | BW6: 50 | BX6: 100 | BY6: 0 | BZ6: 50 | CA6: 50 | CB6: 4 | CC6: 3 | CD6: 2 | CE6: No FRET | CI6: =IF(OR($CE6="",$CE6="No FRET",N($CF6)<=0,N(IF($AI6="",63,$AI6))<=0),"",1/(1+($CF6/IF($AI6="",63,$AI6))^6)) | CJ6: =IF(OR($CE6="",$CE6="No FRET",N($CG6)<=0,N(IF($AJ6="",51,$AJ6))<=0),"",1/(1+($CG6/IF($AJ6="",51,$AJ6))^6)) | CK6: =IF(OR($CE6="",$CE6="No FRET",N($CH6)<=0,N(IF($AK6="",68,$AK6))<=0),"",1/(1+($CH6/IF($AK6="",68,$AK6))^6)) | CL6: =IF(OR($A6="",N($BX6)<=0),"",IF(IF($I6="",5000,$I6)>0,$BX6/(IF($G6="",5000,$G6)*IF($H6="",5000,$H6)*IF($I6="",5000,$I6))/1E-024/6.022E+023/0.000000001,"")) -> 1.3284623 | CM6: =IF(Calc!S6=0,"",IF(Calc!Q6>=1,"✖ saturated (B ≥ freq.)",IF(Calc!Q6>0.1,"⚠ B > 10% of freq.",IF(Calc!Q6=0,"⚠ no brightness",IF(Calc!R6>0.1,"⚠ step > 10% of wr",IF(OR(AND(N($CA6)>0,IF($O6="",1,$O6)<3),AND(N($BZ6)>0,IF($O6="",1,$O6)<2)),"⚠ uses a colour above Colours = "&IF($O6="",1,$O6)&" (ignored)",IF(AND($CE6<>"",$CE6<>"No FRET",N(IF($O6="",1,$O6))<2),"⚠ FRET needs ≥ 2 colours",IF(AND($CE6<>"",$CE6<>"No FRET",N($CF6)+N($CG6)+N($CH6)=0),"⚠ FRET: set R","✔ OK")))))))) -> ✔ OK | DA6: =IF(OR($CW6="",$CW6="No FRET",N($CX6)<=0,N(IF($AI6="",63,$AI6))<=0),"",1/(1+($CX6/IF($AI6="",63,$AI6))^6)) | DB6: =IF(OR($CW6="",$CW6="No FRET",N($CY6)<=0,N(IF($AJ6="",51,$AJ6))<=0),"",1/(1+($CY6/IF($AJ6="",51,$AJ6))^6)) | DC6: =IF(OR($CW6="",$CW6="No FRET",N($CZ6)<=0,N(IF($AK6="",68,$AK6))<=0),"",1/(1+($CZ6/IF($AK6="",68,$AK6))^6)) | DD6: =IF(OR($A6="",N($CP6)<=0),"",IF(IF($I6="",5000,$I6)>0,$CP6/(IF($G6="",5000,$G6)*IF($H6="",5000,$H6)*IF($I6="",5000,$I6))/1E-024/6.022E+023/0.000000001,"")) | DE6: =IF(Calc!Y6=0,"",IF(Calc!W6>=1,"✖ saturated (B ≥ freq.)",IF(Calc!W6>0.1,"⚠ B > 10% of freq.",IF(Calc!W6=0,"⚠ no brightness",IF(Calc!X6>0.1,"⚠ step > 10% of wr",IF(OR(AND(N($CS6)>0,IF($O6="",1,$O6)<3),AND(N($CR6)>0,IF($O6="",1,$O6)<2)),"⚠ uses a colour above Colours = "&IF($O6="",1,$O6)&" (ignored)",IF(AND($CW6<>"",$CW6<>"No FRET",N(IF($O6="",1,$O6))<2),"⚠ FRET needs ≥ 2 colours",IF(AND($CW6<>"",$CW6<>"No FRET",N($CX6)+N($CY6)+N($CZ6)=0),"⚠ FRET: set R","✔ OK")))))))) | DS6: =IF(OR($DO6="",$DO6="No FRET",N($DP6)<=0,N(IF($AI6="",63,$AI6))<=0),"",1/(1+($DP6/IF($AI6="",63,$AI6))^6)) | DT6: =IF(OR($DO6="",$DO6="No FRET",N($DQ6)<=0,N(IF($AJ6="",51,$AJ6))<=0),"",1/(1+($DQ6/IF($AJ6="",51,$AJ6))^6)) | DU6: =IF(OR($DO6="",$DO6="No FRET",N($DR6)<=0,N(IF($AK6="",68,$AK6))<=0),"",1/(1+($DR6/IF($AK6="",68,$AK6))^6)) | DV6: =IF(OR($A6="",N($DH6)<=0),"",IF(IF($I6="",5000,$I6)>0,$DH6/(IF($G6="",5000,$G6)*IF($H6="",5000,$H6)*IF($I6="",5000,$I6))/1E-024/6.022E+023/0.000000001,"")) | DW6: =IF(Calc!AE6=0,"",IF(Calc!AC6>=1,"✖ saturated (B ≥ freq.)",IF(Calc!AC6>0.1,"⚠ B > 10% of freq.",IF(Calc!AC6=0,"⚠ no brightness",IF(Calc!AD6>0.1,"⚠ step > 10% of wr",IF(OR(AND(N($DK6)>0,IF($O6="",1,$O6)<3),AND(N($DJ6)>0,IF($O6="",1,$O6)<2)),"⚠ uses a colour above Colours = "&IF($O6="",1,$O6)&" (ignored)",IF(AND($DO6<>"",$DO6<>"No FRET",N(IF($O6="",1,$O6))<2),"⚠ FRET needs ≥ 2 colours",IF(AND($DO6<>"",$DO6<>"No FRET",N($DP6)+N($DQ6)+N($DR6)=0),"⚠ FRET: set R","✔ OK")))))))) | EK6: =IF(OR($EG6="",$EG6="No FRET",N($EH6)<=0,N(IF($AI6="",63,$AI6))<=0),"",1/(1+($EH6/IF($AI6="",63,$AI6))^6)) | EL6: =IF(OR($EG6="",$EG6="No FRET",N($EI6)<=0,N(IF($AJ6="",51,$AJ6))<=0),"",1/(1+($EI6/IF($AJ6="",51,$AJ6))^6)) | EM6: =IF(OR($EG6="",$EG6="No FRET",N($EJ6)<=0,N(IF($AK6="",68,$AK6))<=0),"",1/(1+($EJ6/IF($AK6="",68,$AK6))^6)) | EN6: =IF(OR($A6="",N($DZ6)<=0),"",IF(IF($I6="",5000,$I6)>0,$DZ6/(IF($G6="",5000,$G6)*IF($H6="",5000,$H6)*IF($I6="",5000,$I6))/1E-024/6.022E+023/0.000000001,"")) | EO6: =IF(Calc!AK6=0,"",IF(Calc!AI6>=1,"✖ saturated (B ≥ freq.)",IF(Calc!AI6>0.1,"⚠ B > 10% of freq.",IF(Calc!AI6=0,"⚠ no brightness",IF(Calc!AJ6>0.1,"⚠ step > 10% of wr",IF(OR(AND(N($EC6)>0,IF($O6="",1,$O6)<3),AND(N($EB6)>0,IF($O6="",1,$O6)<2)),"⚠ uses a colour above Colours = "&IF($O6="",1,$O6)&" (ignored)",IF(AND($EG6<>"",$EG6<>"No FRET",N(IF($O6="",1,$O6))<2),"⚠ FRET needs ≥ 2 colours",IF(AND($EG6<>"",$EG6<>"No FRET",N($EH6)+N($EI6)+N($EJ6)=0),"⚠ FRET: set R","✔ OK")))))))) | EP6: =IF($A6="","",SUM(Calc!G6,Calc!M6,Calc!S6,Calc!Y6,Calc!AE6,Calc!AK6)) -> 3 | EQ6: =IF($A6="","",N($AN6)+N($BF6)+N($BX6)+N($CP6)+N($DH6)+N($DZ6)) -> 1000 | ER6: =IF($A6="","",SUM(Calc!B6,Calc!H6,Calc!N6,Calc!T6,Calc!Z6,Calc!AF6)) -> 28.349298 | ES6: =IF($A6="","",SUM(Calc!C6,Calc!I6,Calc!O6,Calc!U6,Calc!AA6,Calc!AG6)) -> 28.349298 | ET6: =IF($A6="","",SUM(Calc!D6,Calc!J6,Calc!P6,Calc!V6,Calc!AB6,Calc!AH6)) -> 6.299844 | EU6: =IF($A6="","",($ER6+$ES6+$ET6+IF($P6="Yes",N($Q6)*N(IF($O6="",1,$O6)),0))*1000*IF($K6="",10,$K6)/1000000) -> 3.7799064 | EV6: =IF($A6="","",$EU6*1000000*12/1000000000) -> 0.045358877 | EW6: =IF($A6="","",IF($EP6=0,"⚠ no species entered",IF(((LEFT($BC6,1)="✖")+(LEFT($BU6,1)="✖")+(LEFT($CM6,1)="✖")+(LEFT($DE6,1)="✖")+(LEFT($DW6,1)="✖")+(LEFT($EO6,1)="✖"))>0,"✖ "&((LEFT($BC6,1)="✖")+(LEFT($BU6,1)="✖")+(LEFT($CM6,1)="✖")+(LEFT($DE6,1)="✖")+(LEFT($DW6,1)="✖")+(LEFT($EO6,1)="✖"))&" species saturated - see the species checks",IF(MIN(IF($G6="",5000,$G6),IF($H6="",5000,$H6))<8*MAX(IF($T6="",200,$T6),IF($U6="",200,$U6),IF($V6="",200,$V6)),"⚠ box too small laterally (< 8·wr)",IF(AND(IF($I6="",5000,$I6)>0,IF($I6="",5000,$I6)<3*MAX(IF($W6="",1000,$W6),IF($X6="",1000,$X6),IF($Y6="",1000,$Y6))),"⚠ box too small axially (< 3·wz)",IF($EV6>8,"⚠ > 8 GB per file: shorten the duration and use several files",IF(((LEFT($BC6,1)="⚠")+(LEFT($BU6,1)="⚠")+(LEFT($CM6,1)="⚠")+(LEFT($DE6,1)="⚠")+(LEFT($DW6,1)="⚠")+(LEFT($EO6,1)="⚠"))>0,"⚠ "&((LEFT($BC6,1)="⚠")+(LEFT($BU6,1)="⚠")+(LEFT($CM6,1)="⚠")+(LEFT($DE6,1)="⚠")+(LEFT($DW6,1)="⚠")+(LEFT($EO6,1)="⚠"))&" species with a warning","✔ OK"))))))) -> ✔ OK | EX6: 1 | EZ6: .sim | FE6: from Simulation_parameters.xlsx (box size assumed)
A7: S03 | B7: Simulation_complexes_1st_10N_200wr_1000wz_10s_60ns_1000kHz | C7: To test the code in a crowded environment | D7: /Fablab 4/Users/Fabio/PhD/Projects/3C_FCCS/Simulation/Complex | E7: Planned | F7: 3 | G7: 5000 | H7: 5000 | I7: 5000 | J7: 1000 | K7: 10 | L7: 1 | M7: 60 | N7: Point | O7: 3 | P7: No | Q7: 0.2 | R7: No | S7: 250 | T7: 200 | U7: 200 | V7: 200 | W7: 1000 | X7: 1000 | Y7: 1000 | Z7: 0 | AA7: 0 | AB7: 0 | AC7: 0 | AD7: 0 | AE7: 0 | AF7: 0 | AG7: 0 | AH7: 0 | AI7: 63 | AJ7: 51 | AK7: 68 | AL7: Species 1 | AM7: 400 | AN7: 10 | AO7: 10000 | AP7: 0 | AQ7: 0 | AR7: 4 | AS7: 3 | AT7: 2.5 | AU7: No FRET | AY7: =IF(OR($AU7="",$AU7="No FRET",N($AV7)<=0,N(IF($AI7="",63,$AI7))<=0),"",1/(1+($AV7/IF($AI7="",63,$AI7))^6)) | AZ7: =IF(OR($AU7="",$AU7="No FRET",N($AW7)<=0,N(IF($AJ7="",51,$AJ7))<=0),"",1/(1+($AW7/IF($AJ7="",51,$AJ7))^6)) | BA7: =IF(OR($AU7="",$AU7="No FRET",N($AX7)<=0,N(IF($AK7="",68,$AK7))<=0),"",1/(1+($AX7/IF($AK7="",68,$AK7))^6)) | BB7: =IF(OR($A7="",N($AN7)<=0),"",IF(IF($I7="",5000,$I7)>0,$AN7/(IF($G7="",5000,$G7)*IF($H7="",5000,$H7)*IF($I7="",5000,$I7))/1E-024/6.022E+023/0.000000001,"")) -> 0.13284623 | BC7: =IF(Calc!G7=0,"",IF(Calc!E7>=1,"✖ saturated (B ≥ freq.)",IF(Calc!E7>0.1,"⚠ B > 10% of freq.",IF(Calc!E7=0,"⚠ no brightness",IF(Calc!F7>0.1,"⚠ step > 10% of wr",IF(OR(AND(N($AQ7)>0,IF($O7="",1,$O7)<3),AND(N($AP7)>0,IF($O7="",1,$O7)<2)),"⚠ uses a colour above Colours = "&IF($O7="",1,$O7)&" (ignored)",IF(AND($AU7<>"",$AU7<>"No FRET",N(IF($O7="",1,$O7))<2),"⚠ FRET needs ≥ 2 colours",IF(AND($AU7<>"",$AU7<>"No FRET",N($AV7)+N($AW7)+N($AX7)=0),"⚠ FRET: set R","✔ OK")))))))) -> ✖ saturated (B ≥ freq.) | BD7: Species 2 | BE7: 400 | BF7: 10 | BG7: 0 | BH7: 10000 | BI7: 0 | BJ7: 4 | BK7: 3 | BL7: 2.5 | BM7: No FRET | BQ7: =IF(OR($BM7="",$BM7="No FRET",N($BN7)<=0,N(IF($AI7="",63,$AI7))<=0),"",1/(1+($BN7/IF($AI7="",63,$AI7))^6)) | BR7: =IF(OR($BM7="",$BM7="No FRET",N($BO7)<=0,N(IF($AJ7="",51,$AJ7))<=0),"",1/(1+($BO7/IF($AJ7="",51,$AJ7))^6)) | BS7: =IF(OR($BM7="",$BM7="No FRET",N($BP7)<=0,N(IF($AK7="",68,$AK7))<=0),"",1/(1+($BP7/IF($AK7="",68,$AK7))^6)) | BT7: =IF(OR($A7="",N($BF7)<=0),"",IF(IF($I7="",5000,$I7)>0,$BF7/(IF($G7="",5000,$G7)*IF($H7="",5000,$H7)*IF($I7="",5000,$I7))/1E-024/6.022E+023/0.000000001,"")) -> 0.13284623 | BU7: =IF(Calc!M7=0,"",IF(Calc!K7>=1,"✖ saturated (B ≥ freq.)",IF(Calc!K7>0.1,"⚠ B > 10% of freq.",IF(Calc!K7=0,"⚠ no brightness",IF(Calc!L7>0.1,"⚠ step > 10% of wr",IF(OR(AND(N($BI7)>0,IF($O7="",1,$O7)<3),AND(N($BH7)>0,IF($O7="",1,$O7)<2)),"⚠ uses a colour above Colours = "&IF($O7="",1,$O7)&" (ignored)",IF(AND($BM7<>"",$BM7<>"No FRET",N(IF($O7="",1,$O7))<2),"⚠ FRET needs ≥ 2 colours",IF(AND($BM7<>"",$BM7<>"No FRET",N($BN7)+N($BO7)+N($BP7)=0),"⚠ FRET: set R","✔ OK")))))))) -> ✖ saturated (B ≥ freq.) | BV7: Species 3 | BW7: 400 | BX7: 10 | BY7: 0 | BZ7: 0 | CA7: 10000 | CB7: 4 | CC7: 3 | CD7: 2.5 | CE7: No FRET | CI7: =IF(OR($CE7="",$CE7="No FRET",N($CF7)<=0,N(IF($AI7="",63,$AI7))<=0),"",1/(1+($CF7/IF($AI7="",63,$AI7))^6)) | CJ7: =IF(OR($CE7="",$CE7="No FRET",N($CG7)<=0,N(IF($AJ7="",51,$AJ7))<=0),"",1/(1+($CG7/IF($AJ7="",51,$AJ7))^6)) | CK7: =IF(OR($CE7="",$CE7="No FRET",N($CH7)<=0,N(IF($AK7="",68,$AK7))<=0),"",1/(1+($CH7/IF($AK7="",68,$AK7))^6)) | CL7: =IF(OR($A7="",N($BX7)<=0),"",IF(IF($I7="",5000,$I7)>0,$BX7/(IF($G7="",5000,$G7)*IF($H7="",5000,$H7)*IF($I7="",5000,$I7))/1E-024/6.022E+023/0.000000001,"")) -> 0.13284623 | CM7: =IF(Calc!S7=0,"",IF(Calc!Q7>=1,"✖ saturated (B ≥ freq.)",IF(Calc!Q7>0.1,"⚠ B > 10% of freq.",IF(Calc!Q7=0,"⚠ no brightness",IF(Calc!R7>0.1,"⚠ step > 10% of wr",IF(OR(AND(N($CA7)>0,IF($O7="",1,$O7)<3),AND(N($BZ7)>0,IF($O7="",1,$O7)<2)),"⚠ uses a colour above Colours = "&IF($O7="",1,$O7)&" (ignored)",IF(AND($CE7<>"",$CE7<>"No FRET",N(IF($O7="",1,$O7))<2),"⚠ FRET needs ≥ 2 colours",IF(AND($CE7<>"",$CE7<>"No FRET",N($CF7)+N($CG7)+N($CH7)=0),"⚠ FRET: set R","✔ OK")))))))) -> ✖ saturated (B ≥ freq.) | CN7: Species 4 | CO7: 33 | CP7: 10 | CQ7: 10000 | CR7: 10000 | CS7: 10000 | CT7: 4 | CU7: 3 | CV7: 2.5 | CW7: No FRET | DA7: =IF(OR($CW7="",$CW7="No FRET",N($CX7)<=0,N(IF($AI7="",63,$AI7))<=0),"",1/(1+($CX7/IF($AI7="",63,$AI7))^6)) | DB7: =IF(OR($CW7="",$CW7="No FRET",N($CY7)<=0,N(IF($AJ7="",51,$AJ7))<=0),"",1/(1+($CY7/IF($AJ7="",51,$AJ7))^6)) | DC7: =IF(OR($CW7="",$CW7="No FRET",N($CZ7)<=0,N(IF($AK7="",68,$AK7))<=0),"",1/(1+($CZ7/IF($AK7="",68,$AK7))^6)) | DD7: =IF(OR($A7="",N($CP7)<=0),"",IF(IF($I7="",5000,$I7)>0,$CP7/(IF($G7="",5000,$G7)*IF($H7="",5000,$H7)*IF($I7="",5000,$I7))/1E-024/6.022E+023/0.000000001,"")) -> 0.13284623 | DE7: =IF(Calc!Y7=0,"",IF(Calc!W7>=1,"✖ saturated (B ≥ freq.)",IF(Calc!W7>0.1,"⚠ B > 10% of freq.",IF(Calc!W7=0,"⚠ no brightness",IF(Calc!X7>0.1,"⚠ step > 10% of wr",IF(OR(AND(N($CS7)>0,IF($O7="",1,$O7)<3),AND(N($CR7)>0,IF($O7="",1,$O7)<2)),"⚠ uses a colour above Colours = "&IF($O7="",1,$O7)&" (ignored)",IF(AND($CW7<>"",$CW7<>"No FRET",N(IF($O7="",1,$O7))<2),"⚠ FRET needs ≥ 2 colours",IF(AND($CW7<>"",$CW7<>"No FRET",N($CX7)+N($CY7)+N($CZ7)=0),"⚠ FRET: set R","✔ OK")))))))) -> ✖ saturated (B ≥ freq.) | DF7: Species 5 | DG7: 35 | DH7: 10 | DI7: 10000 | DJ7: 10000 | DK7: 0 | DL7: 4 | DM7: 3 | DN7: 2.5 | DO7: No FRET | DS7: =IF(OR($DO7="",$DO7="No FRET",N($DP7)<=0,N(IF($AI7="",63,$AI7))<=0),"",1/(1+($DP7/IF($AI7="",63,$AI7))^6)) | DT7: =IF(OR($DO7="",$DO7="No FRET",N($DQ7)<=0,N(IF($AJ7="",51,$AJ7))<=0),"",1/(1+($DQ7/IF($AJ7="",51,$AJ7))^6)) | DU7: =IF(OR($DO7="",$DO7="No FRET",N($DR7)<=0,N(IF($AK7="",68,$AK7))<=0),"",1/(1+($DR7/IF($AK7="",68,$AK7))^6)) | DV7: =IF(OR($A7="",N($DH7)<=0),"",IF(IF($I7="",5000,$I7)>0,$DH7/(IF($G7="",5000,$G7)*IF($H7="",5000,$H7)*IF($I7="",5000,$I7))/1E-024/6.022E+023/0.000000001,"")) -> 0.13284623 | DW7: =IF(Calc!AE7=0,"",IF(Calc!AC7>=1,"✖ saturated (B ≥ freq.)",IF(Calc!AC7>0.1,"⚠ B > 10% of freq.",IF(Calc!AC7=0,"⚠ no brightness",IF(Calc!AD7>0.1,"⚠ step > 10% of wr",IF(OR(AND(N($DK7)>0,IF($O7="",1,$O7)<3),AND(N($DJ7)>0,IF($O7="",1,$O7)<2)),"⚠ uses a colour above Colours = "&IF($O7="",1,$O7)&" (ignored)",IF(AND($DO7<>"",$DO7<>"No FRET",N(IF($O7="",1,$O7))<2),"⚠ FRET needs ≥ 2 colours",IF(AND($DO7<>"",$DO7<>"No FRET",N($DP7)+N($DQ7)+N($DR7)=0),"⚠ FRET: set R","✔ OK")))))))) -> ✖ saturated (B ≥ freq.) | DX7: Species 6 | DY7: 33 | DZ7: 10 | EA7: 20000 | EB7: 10000 | EC7: 0 | ED7: 4 | EE7: 3 | EF7: 2.5 | EG7: No FRET | EK7: =IF(OR($EG7="",$EG7="No FRET",N($EH7)<=0,N(IF($AI7="",63,$AI7))<=0),"",1/(1+($EH7/IF($AI7="",63,$AI7))^6)) | EL7: =IF(OR($EG7="",$EG7="No FRET",N($EI7)<=0,N(IF($AJ7="",51,$AJ7))<=0),"",1/(1+($EI7/IF($AJ7="",51,$AJ7))^6)) | EM7: =IF(OR($EG7="",$EG7="No FRET",N($EJ7)<=0,N(IF($AK7="",68,$AK7))<=0),"",1/(1+($EJ7/IF($AK7="",68,$AK7))^6)) | EN7: =IF(OR($A7="",N($DZ7)<=0),"",IF(IF($I7="",5000,$I7)>0,$DZ7/(IF($G7="",5000,$G7)*IF($H7="",5000,$H7)*IF($I7="",5000,$I7))/1E-024/6.022E+023/0.000000001,"")) -> 0.13284623 | EO7: =IF(Calc!AK7=0,"",IF(Calc!AI7>=1,"✖ saturated (B ≥ freq.)",IF(Calc!AI7>0.1,"⚠ B > 10% of freq.",IF(Calc!AI7=0,"⚠ no brightness",IF(Calc!AJ7>0.1,"⚠ step > 10% of wr",IF(OR(AND(N($EC7)>0,IF($O7="",1,$O7)<3),AND(N($EB7)>0,IF($O7="",1,$O7)<2)),"⚠ uses a colour above Colours = "&IF($O7="",1,$O7)&" (ignored)",IF(AND($EG7<>"",$EG7<>"No FRET",N(IF($O7="",1,$O7))<2),"⚠ FRET needs ≥ 2 colours",IF(AND($EG7<>"",$EG7<>"No FRET",N($EH7)+N($EI7)+N($EJ7)=0),"⚠ FRET: set R","✔ OK")))))))) -> ✖ saturated (B ≥ freq.) | EP7: =IF($A7="","",SUM(Calc!G7,Calc!M7,Calc!S7,Calc!Y7,Calc!AE7,Calc!AK7)) -> 6 | EQ7: =IF($A7="","",N($AN7)+N($BF7)+N($BX7)+N($CP7)+N($DH7)+N($DZ7)) -> 60 | ER7: =IF($A7="","",SUM(Calc!B7,Calc!H7,Calc!N7,Calc!T7,Calc!Z7,Calc!AF7)) -> 126.7472 | ES7: =IF($A7="","",SUM(Calc!C7,Calc!I7,Calc!O7,Calc!U7,Calc!AA7,Calc!AG7)) -> 117.41309 | ET7: =IF($A7="","",SUM(Calc!D7,Calc!J7,Calc!P7,Calc!V7,Calc!AB7,Calc!AH7)) -> 58.706546 | EU7: =IF($A7="","",($ER7+$ES7+$ET7+IF($P7="Yes",N($Q7)*N(IF($O7="",1,$O7)),0))*1000*IF($K7="",10,$K7)/1000000) -> 3.0286684 | EV7: =IF($A7="","",$EU7*1000000*12/1000000000) -> 0.036344021 | EW7: =IF($A7="","",IF($EP7=0,"⚠ no species entered",IF(((LEFT($BC7,1)="✖")+(LEFT($BU7,1)="✖")+(LEFT($CM7,1)="✖")+(LEFT($DE7,1)="✖")+(LEFT($DW7,1)="✖")+(LEFT($EO7,1)="✖"))>0,"✖ "&((LEFT($BC7,1)="✖")+(LEFT($BU7,1)="✖")+(LEFT($CM7,1)="✖")+(LEFT($DE7,1)="✖")+(LEFT($DW7,1)="✖")+(LEFT($EO7,1)="✖"))&" species saturated - see the species checks",IF(MIN(IF($G7="",5000,$G7),IF($H7="",5000,$H7))<8*MAX(IF($T7="",200,$T7),IF($U7="",200,$U7),IF($V7="",200,$V7)),"⚠ box too small laterally (< 8·wr)",IF(AND(IF($I7="",5000,$I7)>0,IF($I7="",5000,$I7)<3*MAX(IF($W7="",1000,$W7),IF($X7="",1000,$X7),IF($Y7="",1000,$Y7))),"⚠ box too small axially (< 3·wz)",IF($EV7>8,"⚠ > 8 GB per file: shorten the duration and use several files",IF(((LEFT($BC7,1)="⚠")+(LEFT($BU7,1)="⚠")+(LEFT($CM7,1)="⚠")+(LEFT($DE7,1)="⚠")+(LEFT($DW7,1)="⚠")+(LEFT($EO7,1)="⚠"))>0,"⚠ "&((LEFT($BC7,1)="⚠")+(LEFT($BU7,1)="⚠")+(LEFT($CM7,1)="⚠")+(LEFT($DE7,1)="⚠")+(LEFT($DW7,1)="⚠")+(LEFT($EO7,1)="⚠"))&" species with a warning","✔ OK"))))))) -> ✖ 6 species saturated - see the species checks | EX7: 1 | EZ7: .sim | FE7: from Simulation_parameters.xlsx (box size assumed)
A8: S04 | B8: Simulation_complexes_2nd_10N_200wr_1000wz_10s_60ns_1000kHz | C8: To test the code in a crowded environment | D8: /Fablab 4/Users/Fabio/PhD/Projects/3C_FCCS/Simulation/Complex | E8: Planned | F8: 3 | G8: 5000 | H8: 5000 | I8: 5000 | J8: 1000 | K8: 10 | L8: 1 | M8: 60 | N8: Point | O8: 3 | P8: No | Q8: 0.2 | R8: No | S8: 250 | T8: 200 | U8: 200 | V8: 200 | W8: 1000 | X8: 1000 | Y8: 1000 | Z8: 0 | AA8: 0 | AB8: 0 | AC8: 0 | AD8: 0 | AE8: 0 | AF8: 0 | AG8: 0 | AH8: 0 | AI8: 63 | AJ8: 51 | AK8: 68 | AL8: Species 1 | AM8: 400 | AN8: 10 | AO8: 10000 | AP8: 0 | AQ8: 0 | AR8: 4 | AS8: 3 | AT8: 2.5 | AU8: No FRET | AY8: =IF(OR($AU8="",$AU8="No FRET",N($AV8)<=0,N(IF($AI8="",63,$AI8))<=0),"",1/(1+($AV8/IF($AI8="",63,$AI8))^6)) | AZ8: =IF(OR($AU8="",$AU8="No FRET",N($AW8)<=0,N(IF($AJ8="",51,$AJ8))<=0),"",1/(1+($AW8/IF($AJ8="",51,$AJ8))^6)) | BA8: =IF(OR($AU8="",$AU8="No FRET",N($AX8)<=0,N(IF($AK8="",68,$AK8))<=0),"",1/(1+($AX8/IF($AK8="",68,$AK8))^6)) | BB8: =IF(OR($A8="",N($AN8)<=0),"",IF(IF($I8="",5000,$I8)>0,$AN8/(IF($G8="",5000,$G8)*IF($H8="",5000,$H8)*IF($I8="",5000,$I8))/1E-024/6.022E+023/0.000000001,"")) -> 0.13284623 | BC8: =IF(Calc!G8=0,"",IF(Calc!E8>=1,"✖ saturated (B ≥ freq.)",IF(Calc!E8>0.1,"⚠ B > 10% of freq.",IF(Calc!E8=0,"⚠ no brightness",IF(Calc!F8>0.1,"⚠ step > 10% of wr",IF(OR(AND(N($AQ8)>0,IF($O8="",1,$O8)<3),AND(N($AP8)>0,IF($O8="",1,$O8)<2)),"⚠ uses a colour above Colours = "&IF($O8="",1,$O8)&" (ignored)",IF(AND($AU8<>"",$AU8<>"No FRET",N(IF($O8="",1,$O8))<2),"⚠ FRET needs ≥ 2 colours",IF(AND($AU8<>"",$AU8<>"No FRET",N($AV8)+N($AW8)+N($AX8)=0),"⚠ FRET: set R","✔ OK")))))))) -> ✖ saturated (B ≥ freq.) | BD8: Species 2 | BE8: 400 | BF8: 10 | BG8: 0 | BH8: 7000 | BI8: 0 | BJ8: 4 | BK8: 3 | BL8: 2.5 | BM8: No FRET | BQ8: =IF(OR($BM8="",$BM8="No FRET",N($BN8)<=0,N(IF($AI8="",63,$AI8))<=0),"",1/(1+($BN8/IF($AI8="",63,$AI8))^6)) | BR8: =IF(OR($BM8="",$BM8="No FRET",N($BO8)<=0,N(IF($AJ8="",51,$AJ8))<=0),"",1/(1+($BO8/IF($AJ8="",51,$AJ8))^6)) | BS8: =IF(OR($BM8="",$BM8="No FRET",N($BP8)<=0,N(IF($AK8="",68,$AK8))<=0),"",1/(1+($BP8/IF($AK8="",68,$AK8))^6)) | BT8: =IF(OR($A8="",N($BF8)<=0),"",IF(IF($I8="",5000,$I8)>0,$BF8/(IF($G8="",5000,$G8)*IF($H8="",5000,$H8)*IF($I8="",5000,$I8))/1E-024/6.022E+023/0.000000001,"")) -> 0.13284623 | BU8: =IF(Calc!M8=0,"",IF(Calc!K8>=1,"✖ saturated (B ≥ freq.)",IF(Calc!K8>0.1,"⚠ B > 10% of freq.",IF(Calc!K8=0,"⚠ no brightness",IF(Calc!L8>0.1,"⚠ step > 10% of wr",IF(OR(AND(N($BI8)>0,IF($O8="",1,$O8)<3),AND(N($BH8)>0,IF($O8="",1,$O8)<2)),"⚠ uses a colour above Colours = "&IF($O8="",1,$O8)&" (ignored)",IF(AND($BM8<>"",$BM8<>"No FRET",N(IF($O8="",1,$O8))<2),"⚠ FRET needs ≥ 2 colours",IF(AND($BM8<>"",$BM8<>"No FRET",N($BN8)+N($BO8)+N($BP8)=0),"⚠ FRET: set R","✔ OK")))))))) -> ✖ saturated (B ≥ freq.) | BV8: Species 3 | BW8: 400 | BX8: 10 | BY8: 0 | BZ8: 0 | CA8: 5000 | CB8: 4 | CC8: 3 | CD8: 2.5 | CE8: No FRET | CI8: =IF(OR($CE8="",$CE8="No FRET",N($CF8)<=0,N(IF($AI8="",63,$AI8))<=0),"",1/(1+($CF8/IF($AI8="",63,$AI8))^6)) | CJ8: =IF(OR($CE8="",$CE8="No FRET",N($CG8)<=0,N(IF($AJ8="",51,$AJ8))<=0),"",1/(1+($CG8/IF($AJ8="",51,$AJ8))^6)) | CK8: =IF(OR($CE8="",$CE8="No FRET",N($CH8)<=0,N(IF($AK8="",68,$AK8))<=0),"",1/(1+($CH8/IF($AK8="",68,$AK8))^6)) | CL8: =IF(OR($A8="",N($BX8)<=0),"",IF(IF($I8="",5000,$I8)>0,$BX8/(IF($G8="",5000,$G8)*IF($H8="",5000,$H8)*IF($I8="",5000,$I8))/1E-024/6.022E+023/0.000000001,"")) -> 0.13284623 | CM8: =IF(Calc!S8=0,"",IF(Calc!Q8>=1,"✖ saturated (B ≥ freq.)",IF(Calc!Q8>0.1,"⚠ B > 10% of freq.",IF(Calc!Q8=0,"⚠ no brightness",IF(Calc!R8>0.1,"⚠ step > 10% of wr",IF(OR(AND(N($CA8)>0,IF($O8="",1,$O8)<3),AND(N($BZ8)>0,IF($O8="",1,$O8)<2)),"⚠ uses a colour above Colours = "&IF($O8="",1,$O8)&" (ignored)",IF(AND($CE8<>"",$CE8<>"No FRET",N(IF($O8="",1,$O8))<2),"⚠ FRET needs ≥ 2 colours",IF(AND($CE8<>"",$CE8<>"No FRET",N($CF8)+N($CG8)+N($CH8)=0),"⚠ FRET: set R","✔ OK")))))))) -> ✖ saturated (B ≥ freq.) | CN8: Species 4 | CO8: 33 | CP8: 10 | CQ8: 10000 | CR8: 7000 | CS8: 5000 | CT8: 4 | CU8: 3 | CV8: 2.5 | CW8: No FRET | DA8: =IF(OR($CW8="",$CW8="No FRET",N($CX8)<=0,N(IF($AI8="",63,$AI8))<=0),"",1/(1+($CX8/IF($AI8="",63,$AI8))^6)) | DB8: =IF(OR($CW8="",$CW8="No FRET",N($CY8)<=0,N(IF($AJ8="",51,$AJ8))<=0),"",1/(1+($CY8/IF($AJ8="",51,$AJ8))^6)) | DC8: =IF(OR($CW8="",$CW8="No FRET",N($CZ8)<=0,N(IF($AK8="",68,$AK8))<=0),"",1/(1+($CZ8/IF($AK8="",68,$AK8))^6)) | DD8: =IF(OR($A8="",N($CP8)<=0),"",IF(IF($I8="",5000,$I8)>0,$CP8/(IF($G8="",5000,$G8)*IF($H8="",5000,$H8)*IF($I8="",5000,$I8))/1E-024/6.022E+023/0.000000001,"")) -> 0.13284623 | DE8: =IF(Calc!Y8=0,"",IF(Calc!W8>=1,"✖ saturated (B ≥ freq.)",IF(Calc!W8>0.1,"⚠ B > 10% of freq.",IF(Calc!W8=0,"⚠ no brightness",IF(Calc!X8>0.1,"⚠ step > 10% of wr",IF(OR(AND(N($CS8)>0,IF($O8="",1,$O8)<3),AND(N($CR8)>0,IF($O8="",1,$O8)<2)),"⚠ uses a colour above Colours = "&IF($O8="",1,$O8)&" (ignored)",IF(AND($CW8<>"",$CW8<>"No FRET",N(IF($O8="",1,$O8))<2),"⚠ FRET needs ≥ 2 colours",IF(AND($CW8<>"",$CW8<>"No FRET",N($CX8)+N($CY8)+N($CZ8)=0),"⚠ FRET: set R","✔ OK")))))))) -> ✖ saturated (B ≥ freq.) | DF8: Species 5 | DG8: 33 | DH8: 10 | DI8: 20000 | DJ8: 7000 | DK8: 0 | DL8: 4 | DM8: 3 | DN8: 2.5 | DO8: No FRET | DS8: =IF(OR($DO8="",$DO8="No FRET",N($DP8)<=0,N(IF($AI8="",63,$AI8))<=0),"",1/(1+($DP8/IF($AI8="",63,$AI8))^6)) | DT8: =IF(OR($DO8="",$DO8="No FRET",N($DQ8)<=0,N(IF($AJ8="",51,$AJ8))<=0),"",1/(1+($DQ8/IF($AJ8="",51,$AJ8))^6)) | DU8: =IF(OR($DO8="",$DO8="No FRET",N($DR8)<=0,N(IF($AK8="",68,$AK8))<=0),"",1/(1+($DR8/IF($AK8="",68,$AK8))^6)) | DV8: =IF(OR($A8="",N($DH8)<=0),"",IF(IF($I8="",5000,$I8)>0,$DH8/(IF($G8="",5000,$G8)*IF($H8="",5000,$H8)*IF($I8="",5000,$I8))/1E-024/6.022E+023/0.000000001,"")) -> 0.13284623 | DW8: =IF(Calc!AE8=0,"",IF(Calc!AC8>=1,"✖ saturated (B ≥ freq.)",IF(Calc!AC8>0.1,"⚠ B > 10% of freq.",IF(Calc!AC8=0,"⚠ no brightness",IF(Calc!AD8>0.1,"⚠ step > 10% of wr",IF(OR(AND(N($DK8)>0,IF($O8="",1,$O8)<3),AND(N($DJ8)>0,IF($O8="",1,$O8)<2)),"⚠ uses a colour above Colours = "&IF($O8="",1,$O8)&" (ignored)",IF(AND($DO8<>"",$DO8<>"No FRET",N(IF($O8="",1,$O8))<2),"⚠ FRET needs ≥ 2 colours",IF(AND($DO8<>"",$DO8<>"No FRET",N($DP8)+N($DQ8)+N($DR8)=0),"⚠ FRET: set R","✔ OK")))))))) -> ✖ saturated (B ≥ freq.) | EK8: =IF(OR($EG8="",$EG8="No FRET",N($EH8)<=0,N(IF($AI8="",63,$AI8))<=0),"",1/(1+($EH8/IF($AI8="",63,$AI8))^6)) | EL8: =IF(OR($EG8="",$EG8="No FRET",N($EI8)<=0,N(IF($AJ8="",51,$AJ8))<=0),"",1/(1+($EI8/IF($AJ8="",51,$AJ8))^6)) | EM8: =IF(OR($EG8="",$EG8="No FRET",N($EJ8)<=0,N(IF($AK8="",68,$AK8))<=0),"",1/(1+($EJ8/IF($AK8="",68,$AK8))^6)) | EN8: =IF(OR($A8="",N($DZ8)<=0),"",IF(IF($I8="",5000,$I8)>0,$DZ8/(IF($G8="",5000,$G8)*IF($H8="",5000,$H8)*IF($I8="",5000,$I8))/1E-024/6.022E+023/0.000000001,"")) | EO8: =IF(Calc!AK8=0,"",IF(Calc!AI8>=1,"✖ saturated (B ≥ freq.)",IF(Calc!AI8>0.1,"⚠ B > 10% of freq.",IF(Calc!AI8=0,"⚠ no brightness",IF(Calc!AJ8>0.1,"⚠ step > 10% of wr",IF(OR(AND(N($EC8)>0,IF($O8="",1,$O8)<3),AND(N($EB8)>0,IF($O8="",1,$O8)<2)),"⚠ uses a colour above Colours = "&IF($O8="",1,$O8)&" (ignored)",IF(AND($EG8<>"",$EG8<>"No FRET",N(IF($O8="",1,$O8))<2),"⚠ FRET needs ≥ 2 colours",IF(AND($EG8<>"",$EG8<>"No FRET",N($EH8)+N($EI8)+N($EJ8)=0),"⚠ FRET: set R","✔ OK")))))))) | EP8: =IF($A8="","",SUM(Calc!G8,Calc!M8,Calc!S8,Calc!Y8,Calc!AE8,Calc!AK8)) -> 5 | EQ8: =IF($A8="","",N($AN8)+N($BF8)+N($BX8)+N($CP8)+N($DH8)+N($DZ8)) -> 50 | ER8: =IF($A8="","",SUM(Calc!B8,Calc!H8,Calc!N8,Calc!T8,Calc!Z8,Calc!AF8)) -> 97.393931 | ES8: =IF($A8="","",SUM(Calc!C8,Calc!I8,Calc!O8,Calc!U8,Calc!AA8,Calc!AG8)) -> 74.760097 | ET8: =IF($A8="","",SUM(Calc!D8,Calc!J8,Calc!P8,Calc!V8,Calc!AB8,Calc!AH8)) -> 41.974775 | EU8: =IF($A8="","",($ER8+$ES8+$ET8+IF($P8="Yes",N($Q8)*N(IF($O8="",1,$O8)),0))*1000*IF($K8="",10,$K8)/1000000) -> 2.141288 | EV8: =IF($A8="","",$EU8*1000000*12/1000000000) -> 0.025695456 | EW8: =IF($A8="","",IF($EP8=0,"⚠ no species entered",IF(((LEFT($BC8,1)="✖")+(LEFT($BU8,1)="✖")+(LEFT($CM8,1)="✖")+(LEFT($DE8,1)="✖")+(LEFT($DW8,1)="✖")+(LEFT($EO8,1)="✖"))>0,"✖ "&((LEFT($BC8,1)="✖")+(LEFT($BU8,1)="✖")+(LEFT($CM8,1)="✖")+(LEFT($DE8,1)="✖")+(LEFT($DW8,1)="✖")+(LEFT($EO8,1)="✖"))&" species saturated - see the species checks",IF(MIN(IF($G8="",5000,$G8),IF($H8="",5000,$H8))<8*MAX(IF($T8="",200,$T8),IF($U8="",200,$U8),IF($V8="",200,$V8)),"⚠ box too small laterally (< 8·wr)",IF(AND(IF($I8="",5000,$I8)>0,IF($I8="",5000,$I8)<3*MAX(IF($W8="",1000,$W8),IF($X8="",1000,$X8),IF($Y8="",1000,$Y8))),"⚠ box too small axially (< 3·wz)",IF($EV8>8,"⚠ > 8 GB per file: shorten the duration and use several files",IF(((LEFT($BC8,1)="⚠")+(LEFT($BU8,1)="⚠")+(LEFT($CM8,1)="⚠")+(LEFT($DE8,1)="⚠")+(LEFT($DW8,1)="⚠")+(LEFT($EO8,1)="⚠"))>0,"⚠ "&((LEFT($BC8,1)="⚠")+(LEFT($BU8,1)="⚠")+(LEFT($CM8,1)="⚠")+(LEFT($DE8,1)="⚠")+(LEFT($DW8,1)="⚠")+(LEFT($EO8,1)="⚠"))&" species with a warning","✔ OK"))))))) -> ✖ 5 species saturated - see the species checks | EX8: 1 | EZ8: .sim | FE8: from Simulation_parameters.xlsx (box size assumed)
